Workbook

Sheet 입금현황
A1: =COUNTIFS(B2:B44,"유지") | B1: Status | C1: 누적입금액 | D1: 26년 5월 | E1: 26년 6월 | F1: 26년 7월 | G1: 26년 8월 | H1: 26년 9월 | I1: 26년 10월 | J1: 26년 11월 | K1: 26년 12월 | L1: 27년 1월 | M1: 27년 2월 | N1: 27년 3월 | O1: 27년 4월 | P1: 27년 5월 | Q1: 27년 6월 | R1: 27년 7월 | S1: 27년 8월 | T1: 27년 9월 | U1: 27년 10월 | V1: 27년 11월 | W1: 27년 12월
A2: 김산 | B2: 유지 | C2: =SUM(D2:CD2) | D2: 20000 | E2: 20000 | F2: 20000 | G2: 20000 | H2: 20000
A3: 이형석 | B3: 유지 | C3: =SUM(D3:CD3) | D3: 20000 | E3: 20000 | F3: 20000 | G3: 20000 | H3: 20000
A4: 이현우 | B4: 유지 | C4: =SUM(D4:CD4) | D4: 20000 | E4: 20000 | F4: 20000 | G4: 20000 | H4: 20000 | I4: 20000
A5: 윤석원 | B5: 유지 | C5: =SUM(D5:CD5) | D5: 20000 | E5: 20000 | F5: 20000 | G5: 20000 | H5: 20000
A6: 임승언 | B6: 유지 | C6: =SUM(D6:CD6) | D6: 20000 | E6: 20000 | F6: 20000 | G6: 20000 | H6: 20000
A7: 나한영 | B7: 유지 | C7: =SUM(D7:CD7) | D7: 20000 | E7: 20000 | F7: 20000 | G7: 20000 | H7: 20000 | I7: 20000
A8: 홍경택 | B8: 유지 | C8: =SUM(D8:CD8) | D8: 20000 | E8: 20000 | F8: 20000 | G8: 20000 | H8: 20000 | I8: 20000
A9: 김수민 | B9: 유지 | C9: =SUM(D9:CD9) | D9: 20000 | E9: 20000
A10: 이정승 | B10: 유지 | C10: =SUM(D10:CD10) | D10: 20000 | E10: 20000 | F10: 20000 | G10: 20000 | H10: 20000
A11: 박병우 | B11: 유지 | C11: =SUM(D11:CD11) | D11: 20000 | E11: 20000 | F11: 20000 | G11: 20000 | H11: 20000 | I11: 20000 | J11: 20000
A12: 임익준 | B12: 유지 | C12: =SUM(D12:CD12) | D12: 20000 | E12: 20000 | F12: 20000 | G12: 20000 | H12: 20000 | I12: 20000 | J12: 20000 | K12: 20000
A13: 김대우 | B13: 유지 | C13: =SUM(D13:CD13) | D13: 20000 | E13: 20000 | F13: 20000 | G13: 20000 | H13: 20000 | I13: 20000
A14: 최창환 | B14: 유지 | C14: =SUM(D14:CD14) | D14: 20000 | E14: 20000 | F14: 20000 | G14: 20000 | H14: 20000
A15: 김성환(82) | B15: 유지 | C15: =SUM(D15:CD15) | D15: 20000 | E15: 20000 | F15: 20000 | G15: 20000 | H15: 20000 | I15: 20000
A16: 권기표 | B16: 유지 | C16: =SUM(D16:CD16) | D16: 20000 | E16: 20000 | F16: 20000 | G16: 20000 | H16: 20000 | I16: 20000
A17: 윤준원 | B17: 유지 | C17: =SUM(D17:CD17) | D17: 20000 | E17: 20000 | F17: 20000 | G17: 20000
A18: 류성준 | B18: 유지 | C18: =SUM(D18:CD18) | D18: 20000 | E18: 20000 | F18: 20000 | G18: 20000 | H18: 20000
A19: 윤현호 | B19: 유지 | C19: =SUM(D19:CD19) | D19: 20000 | E19: 20000 | F19: 20000 | G19: 20000 | H19: 20000 | I19: 20000
A20: 황인호 | B20: 유지 | C20: =SUM(D20:CD20) | D20: 20000 | E20: 20000 | F20: 20000 | G20: 20000 | H20: 20000
A21: 손원우 | B21: 탈퇴 | C21: =SUM(D21:CD21) | D21: 20000 | E21: 0
A22: 조성태 | B22: 유지 | C22: =SUM(D22:CD22) | D22: 20000 | E22: 20000 | F22: 20000
A23: 이은광 | B23: 유지 | C23: =SUM(D23:CD23) | D23: 20000 | E23: 20000 | F23: 20000 | G23: 20000 | H23: 20000 | I23: 20000 | J23: 20000 | K23: 20000
A24: 강현수 | B24: 유지 | C24: =SUM(D24:CD24) | D24: 20000 | E24: 20000 | F24: 20000 | G24: 20000 | H24: 20000
A25: 조현민 | B25: 유지 | C25: =SUM(D25:CD25) | D25: 20000 | E25: 20000 | F25: 20000 | G25: 20000 | H25: 20000
A26: 김성환(92) | B26: 유지 | C26: =SUM(D26:CD26) | D26: 20000 | E26: 20000 | F26: 20000 | G26: 20000 | H26: 20000 | I26: 20000
A27: 이준범 | B27: 유지 | C27: =SUM(D27:CD27) | D27: 20000 | E27: 20000 | F27: 20000 | G27: 20000 | H27: 20000
A28: 황호연 | B28: 탈퇴 | C28: =SUM(D28:CD28) | D28: 20000 | E28: 0
A29: 이건희 | B29: 유지 | C29: =SUM(D29:CD29) | D29: 20000 | E29: 20000 | F29: 20000 | G29: 20000 | H29: 20000 | I29: 20000
A30: 김준기 | B30: 유지 | C30: =SUM(D30:CD30) | D30: 20000 | E30: 20000 | F30: 20000 | G30: 20000 | H30: 20000 | I30: 20000
A31: 백근호 | B31: 유지 | C31: =SUM(D31:CD31) | D31: 20000 | E31: 20000 | F31: 20000 | G31: 20000 | H31: 20000 | I31: 20000
A32: 김현섭 | B32: 유지 | C32: =SUM(D32:CD32) | D32: 20000 | E32: 20000 | F32: 20000 | G32: 20000
A33: 김지수 | B33: 탈퇴 | C33: =SUM(D33:CD33) | D33: 20000
A34: 최원재 | B34: 유지 | C34: =SUM(D34:CD34) | D34: 20000 | E34: 20000 | F34: 20000 | G34: 20000 | H34: 20000 | I34: 20000
A35: 김서래 | B35: 탈퇴 | C35: =SUM(D35:CD35) | D35: 20000 | E35: 20000
A36: 이호준 | B36: 유지 | C36: =SUM(D36:CD36) | D36: 20000 | E36: 20000 | F36: 20000 | G36: 20000 | H36: 20000
A37: 강충현 | B37: 유지 | C37: =SUM(D37:CD37) | D37: 20000 | E37: 20000 | F37: 20000 | G37: 20000 | H37: 20000 | I37: 20000
A38: 박헌우 | B38: 유지 | C38: 40000 | D38: 20000 | E38: 20000 | F38: 20000 | G38: 20000 | H38: 20000 | I38: 20000 | J38: 20000 | K38: 20000
A39: 옥지엽 | B39: 유지 | C39: =SUM(D39:CD39) | D39: 20000 | E39: 20000 | F39: 20000 | G39: 20000 | H39: 20000 | I39: 20000
A40: 서정권 | B40: 유지 | C40: =SUM(D40:CD40) | D40: 20000 | E40: 20000 | F40: 20000 | G40: 20000 | H40: 20000
...

Sheet 회비입출내역
C1: =참고!$E$5 | F1: =참고!$D$5
A2: 구분 | C2: 전월 | F2: 당월 | I2: 누적
A4: 입금 | D4: =SUM(C5:C7) | G4: =SUM(F5:F7) | J4: =SUM(I5:I7)
A5: 회비 | C5: =SUMIFS(원장!$H:$H,원장!$E:$E,회비입출내역!$A5,원장!$A:$A,회비입출내역!$C$1) | F5: =SUMIFS(원장!$H:$H,원장!$E:$E,회비입출내역!$A5,원장!$A:$A,회비입출내역!$F$1) | I5: =SUMIFS(원장!$H:$H,원장!$E:$E,회비입출내역!$A5)
A6: 지각비 | C6: =SUMIFS(원장!$H:$H,원장!$E:$E,회비입출내역!$A6,원장!$A:$A,회비입출내역!$C$1) | F6: =SUMIFS(원장!$H:$H,원장!$E:$E,회비입출내역!$A6,원장!$A:$A,회비입출내역!$F$1) | I6: =SUMIFS(원장!$H:$H,원장!$E:$E,회비입출내역!$A6)
A7: 이자 | C7: =SUMIFS(원장!$H:$H,원장!$E:$E,회비입출내역!$A7,원장!$A:$A,회비입출내역!$C$1) | F7: =SUMIFS(원장!$H:$H,원장!$E:$E,회비입출내역!$A7,원장!$A:$A,회비입출내역!$F$1) | I7: =SUMIFS(원장!$H:$H,원장!$E:$E,회비입출내역!$A7)
A9: 출금 | D9: =SUM(C10:C15) | G9: =SUM(F10:F15) | J9: =SUM(I10:I15)
A10: 모임비 | C10: =SUMIFS(원장!$H:$H,원장!$E:$E,회비입출내역!$A10,원장!$A:$A,회비입출내역!$C$1) | F10: =SUMIFS(원장!$H:$H,원장!$E:$E,회비입출내역!$A10,원장!$A:$A,회비입출내역!$F$1) | I10: =SUMIFS(원장!$H:$H,원장!$E:$E,회비입출내역!$A10)
A11: 강연비 | C11: =SUMIFS(원장!$H:$H,원장!$E:$E,회비입출내역!$A11,원장!$A:$A,회비입출내역!$C$1) | F11: =SUMIFS(원장!$H:$H,원장!$E:$E,회비입출내역!$A11,원장!$A:$A,회비입출내역!$F$1) | I11: =SUMIFS(원장!$H:$H,원장!$E:$E,회비입출내역!$A11)
A12: 경조사비 | C12: =SUMIFS(원장!$H:$H,원장!$E:$E,회비입출내역!$A12,원장!$A:$A,회비입출내역!$C$1) | F12: =SUMIFS(원장!$H:$H,원장!$E:$E,회비입출내역!$A12,원장!$A:$A,회비입출내역!$F$1) | I12: =SUMIFS(원장!$H:$H,원장!$E:$E,회비입출내역!$A12)
A13: 경품비 | C13: =SUMIFS(원장!$H:$H,원장!$E:$E,회비입출내역!$A13,원장!$A:$A,회비입출내역!$C$1) | F13: =SUMIFS(원장!$H:$H,원장!$E:$E,회비입출내역!$A13,원장!$A:$A,회비입출내역!$F$1) | I13: =SUMIFS(원장!$H:$H,원장!$E:$E,회비입출내역!$A13)
A15: 입금 - 출금 | D15: =SUM(D4:D13) | G15: =SUM(G4:G13) | J15: =SUM(J4:J13)
I16: 8월 3일 잔액 | J16: 1398271
J17: =J16=J15
J18: =J15-J16

Sheet 원장
A1: 연월 | B1: 요일 | C1: 일자 | D1: 분류1 | E1: 분류2 | F1: 차변 | G1: 대변 | H1: 대변-차변 | I1: 비고
A2: 수식 | B2: 수식 | C2: 입력 | D2: 입력 | E2: 입력 | F2: 입력 | G2: 입력 | H2: 수식 | I2: 입력
A3: =RIGHT(YEAR(C3),2)&"년 "&MONTH(C3)&"월" | B3: =VLOOKUP(WEEKDAY(C3,2),참조!$A$1:$B$10,2,) | C3: 46143 | D3: 입금 | E3: 회비 | G3: =SUMIFS(입금현황!$46:$46,입금현황!$1:$1,원장!$A3) | H3: =G3-F3 | I3: 월간회비납부
A4: =RIGHT(YEAR(C4),2)&"년 "&MONTH(C4)&"월" | B4: =VLOOKUP(WEEKDAY(C4,2),참조!$A$1:$B$10,2,) | C4: 46173 | D4: 입금 | E4: 이자 | G4: 27 | H4: =G4-F4 | I4: 월간이자_잔액맞추기용
A5: =RIGHT(YEAR(C5),2)&"년 "&MONTH(C5)&"월" | B5: =VLOOKUP(WEEKDAY(C5,2),참조!$A$1:$B$10,2,) | C5: 46159 | D5: 출금 | E5: 모임비 | F5: 410600 | H5: =G5-F5 | I5: 권기표, 상품 등
A6: =RIGHT(YEAR(C6),2)&"년 "&MONTH(C6)&"월" | B6: =VLOOKUP(WEEKDAY(C6,2),참조!$A$1:$B$10,2,) | C6: 46174 | D6: 입금 | E6: 회비 | G6: =SUMIFS(입금현황!$46:$46,입금현황!$1:$1,원장!$A6) | H6: =G6-F6 | I6: 월간회비납부
A7: =RIGHT(YEAR(C7),2)&"년 "&MONTH(C7)&"월" | B7: =VLOOKUP(WEEKDAY(C7,2),참조!$A$1:$B$10,2,) | C7: 46174 | D7: 출금 | E7: 모임비 | F7: 94300 | H7: =G7-F7 | I7: 황인호, 현수막 제작 등 (은행확인 6/1)
A8: =RIGHT(YEAR(C8),2)&"년 "&MONTH(C8)&"월" | B8: =VLOOKUP(WEEKDAY(C8,2),참조!$A$1:$B$10,2,) | C8: 46185 | D8: 출금 | E8: 경품비 | F8: 180000 | H8: =G8-F8 | I8: 대회 당일 카카오페이 정산(6건)
A9: =RIGHT(YEAR(C9),2)&"년 "&MONTH(C9)&"월" | B9: =VLOOKUP(WEEKDAY(C9,2),참조!$A$1:$B$10,2,) | C9: 46185 | D9: 출금 | E9: 경품비 | F9: 90000 | H9: =G9-F9 | I9: 옥지엽 이체
A10: =RIGHT(YEAR(C10),2)&"년 "&MONTH(C10)&"월" | B10: =VLOOKUP(WEEKDAY(C10,2),참조!$A$1:$B$10,2,) | C10: 46187 | D10: 출금 | E10: 모임비 | F10: 328000 | H10: =G10-F10 | I10: 황인호, 술값
A11: =RIGHT(YEAR(C11),2)&"년 "&MONTH(C11)&"월" | B11: =VLOOKUP(WEEKDAY(C11,2),참조!$A$1:$B$10,2,) | C11: 46200 | D11: 입금 | E11: 이자 | G11: 63 | H11: =G11-F11 | I11: 월간이자
A12: =RIGHT(YEAR(C12),2)&"년 "&MONTH(C12)&"월" | B12: =VLOOKUP(WEEKDAY(C12,2),참조!$A$1:$B$10,2,) | C12: 46204 | D12: 입금 | E12: 회비 | G12: =SUMIFS(입금현황!$46:$46,입금현황!$1:$1,원장!$A12) | H12: =G12-F12 | I12: 월간회비납부
A13: =RIGHT(YEAR(C13),2)&"년 "&MONTH(C13)&"월" | B13: =VLOOKUP(WEEKDAY(C13,2),참조!$A$1:$B$10,2,) | C13: 46235 | D13: 입금 | E13: 회비 | G13: =SUMIFS(입금현황!$46:$46,입금현황!$1:$1,원장!$A13) | H13: =G13-F13 | I13: 월간회비납부
A14: =RIGHT(YEAR(C14),2)&"년 "&MONTH(C14)&"월" | B14: =VLOOKUP(WEEKDAY(C14,2),참조!$A$1:$B$10,2,) | C14: 46266 | D14: 입금 | E14: 회비 | G14: =SUMIFS(입금현황!$46:$46,입금현황!$1:$1,원장!$A14) | H14: =G14-F14 | I14: 월간회비납부
A15: =RIGHT(YEAR(C15),2)&"년 "&MONTH(C15)&"월" | B15: =VLOOKUP(WEEKDAY(C15,2),참조!$A$1:$B$10,2,) | C15: 46296 | D15: 입금 | E15: 회비 | G15: =SUMIFS(입금현황!$46:$46,입금현황!$1:$1,원장!$A15) | H15: =G15-F15 | I15: 월간회비납부
A16: =RIGHT(YEAR(C16),2)&"년 "&MONTH(C16)&"월" | B16: =VLOOKUP(WEEKDAY(C16,2),참조!$A$1:$B$10,2,) | C16: 46327 | D16: 입금 | E16: 회비 | G16: =SUMIFS(입금현황!$46:$46,입금현황!$1:$1,원장!$A16) | H16: =G16-F16 | I16: 월간회비납부
A17: =RIGHT(YEAR(C17),2)&"년 "&MONTH(C17)&"월" | B17: =VLOOKUP(WEEKDAY(C17,2),참조!$A$1:$B$10,2,) | C17: 46357 | D17: 입금 | E17: 회비 | G17: =SUMIFS(입금현황!$46:$46,입금현황!$1:$1,원장!$A17) | H17: =G17-F17 | I17: 월간회비납부
A18: =RIGHT(YEAR(C18),2)&"년 "&MONTH(C18)&"월" | B18: =VLOOKUP(WEEKDAY(C18,2),참조!$A$1:$B$10,2,) | C18: 46222 | D18: 출금 | E18: 모임비 | F18: 559000 | H18: =G18-F18 | I18: 카카오페이 자동이체, 7월 모임비
A19: =RIGHT(YEAR(C19),2)&"년 "&MONTH(C19)&"월" | B19: =VLOOKUP(WEEKDAY(C19,2),참조!$A$1:$B$10,2,) | C19: 46228 | D19: 입금 | E19: 이자 | G19: 81 | H19: =G19-F19 | I19: 월간이자
A20: =RIGHT(YEAR(C20),2)&"년 "&MONTH(C20)&"월" | B20: =VLOOKUP(WEEKDAY(C20,2),참조!$A$1:$B$10,2,) | C20: 46388 | D20: 입금 | E20: 회비 | G20: =SUMIFS(입금현황!$46:$46,입금현황!$1:$1,원장!$A20) | H20: =G20-F20 | I20: 월간회비납부
A21: =RIGHT(YEAR(C21),2)&"년 "&MONTH(C21)&"월" | B21: =VLOOKUP(WEEKDAY(C21,2),참조!$A$1:$B$10,2,) | C21: 46263 | D21: 입금 | E21: 이자 | G21: 115 | H21: =G21-F21 | I21: 예금이자(8월)
A23: =RIGHT(YEAR(C23),2)&"년 "&MONTH(C23)&"월" | B23: =VLOOKUP(WEEKDAY(C23,2),참조!$A$1:$B$10,2,) | C23: 46277 | D23: 출금 | E23: 모임비 | F23: 262000 | H23: =G23-F23 | I23: 점심식대
A24: =RIGHT(YEAR(C24),2)&"년 "&MONTH(C24)&"월" | B24: =VLOOKUP(WEEKDAY(C24,2),참조!$A$1:$B$10,2,) | C24: 46291 | D24: 입금 | E24: 이자 | G24: 129 | H24: =G24-F24 | I24: 입출금통장 이자

Sheet 증감분석
B2: 연월 | C2: 개월수 역산 | D2: 입금 | H2: 출금
B3: 연월 | C3: 개월수 역산 | D3: 회비 | E3: 지각비 | F3: 이자 | G3: 계 | H3: 모임비 | I3: 강연비 | J3: 경조사비 | K3: 경품비 | L3: 계
B4: 전체평균 | D4: =AVERAGEIFS(D10:D2203,D10:D2203,">0") | E4: =AVERAGEIFS(E10:E2203,E10:E2203,">0") | F4: =AVERAGEIFS(F10:F2203,F10:F2203,">0") | G4: =AVERAGEIFS(G10:G2203,G10:G2203,">0") | H4: =AVERAGEIFS(H10:H2203,H10:H2203,"<0") | I4: =AVERAGEIFS(I10:I2203,I10:I2203,"<0") | J4: =AVERAGEIFS(J10:J2203,J10:J2203,"<0") | K4: =AVERAGEIFS(K10:K2203,K10:K2203,"<0") | L4: =AVERAGEIFS(L10:L2203,L10:L2203,"<0")
A5: 3 | B5: 최근3개월평균 | D5: =AVERAGEIFS(D8:D2201,$C$10:$C$2203,"<=3") | E5: =AVERAGEIFS(E8:E2201,$C$10:$C$2203,"<=3") | F5: =AVERAGEIFS(F8:F2201,$C$10:$C$2203,"<=3") | G5: =AVERAGEIFS(G8:G2201,$C$10:$C$2203,"<=3") | H5: =AVERAGEIFS(H$10:H$2203,$C$10:$C$2203,"<=3") | I5: =AVERAGEIFS(I$10:I$2203,$C$10:$C$2203,"<=3") | J5: =AVERAGEIFS(J$10:J$2203,$C$10:$C$2203,"<=3") | K5: =AVERAGEIFS(K$10:K$2203,$C$10:$C$2203,"<=3") | L5: =AVERAGEIFS(L$10:L$2203,$C$10:$C$2203,"<=3")
A6: 6 | B6: 최근6개월평균 | D6: =AVERAGEIFS(D9:D2202,$C$10:$C$2203,"<=6") | E6: =AVERAGEIFS(E9:E2202,$C$10:$C$2203,"<=6") | F6: =AVERAGEIFS(F9:F2202,$C$10:$C$2203,"<=6") | G6: =AVERAGEIFS(G9:G2202,$C$10:$C$2203,"<=6") | H6: =AVERAGEIFS(H$10:H$2203,$C$10:$C$2203,"<=6") | I6: =AVERAGEIFS(I$10:I$2203,$C$10:$C$2203,"<=6") | J6: =AVERAGEIFS(J$10:J$2203,$C$10:$C$2203,"<=6") | K6: =AVERAGEIFS(K$10:K$2203,$C$10:$C$2203,"<=6") | L6: =AVERAGEIFS(L$10:L$2203,$C$10:$C$2203,"<=6")
A7: 12 | B7: 최근12개월평균 | D7: =AVERAGEIFS(D10:D2203,$C$10:$C$2203,"<=12") | E7: =AVERAGEIFS(E10:E2203,$C$10:$C$2203,"<=12") | F7: =AVERAGEIFS(F10:F2203,$C$10:$C$2203,"<=12") | G7: =AVERAGEIFS(G10:G2203,$C$10:$C$2203,"<=12") | H7: =AVERAGEIFS(H$10:H$2203,$C$10:$C$2203,"<=12") | I7: =AVERAGEIFS(I$10:I$2203,$C$10:$C$2203,"<=12") | J7: =AVERAGEIFS(J$10:J$2203,$C$10:$C$2203,"<=12") | K7: =AVERAGEIFS(K$10:K$2203,$C$10:$C$2203,"<=12") | L7: =AVERAGEIFS(L$10:L$2203,$C$10:$C$2203,"<=12")
B9: 연월 | C9: 개월수 역산 | D9: 입금 | E9: 입금 | F9: 입금 | G9: 입금 | H9: 출금 | I9: 출금 | J9: 출금 | K9: 출금 | L9: 출금 | M9: 입금-출금 | P9: 차트용
B10: 연월 | C10: 개월수 역산 | D10: 회비 | E10: 지각비 | F10: 이자 | G10: 계 | H10: 모임비 | I10: 강연비 | J10: 경조사비 | K10: 경품비 | L10: 계 | M10: 계 | N10: 누적 | P10: 연월 | Q10: 입금 | R10: 출금 | S10: 누적
B11: 24년 6월 | C11: =IF($B11=참고!$D$5,1,C12+1) | D11: =SUMIFS(원장!$H:$H,원장!$A:$A,증감분석!$B11,원장!$D:$D,증감분석!D$9,원장!$E:$E,증감분석!D$10) | E11: =SUMIFS(원장!$H:$H,원장!$A:$A,증감분석!$B11,원장!$D:$D,증감분석!E$9,원장!$E:$E,증감분석!E$10) | F11: =SUMIFS(원장!$H:$H,원장!$A:$A,증감분석!$B11,원장!$D:$D,증감분석!F$9,원장!$E:$E,증감분석!F$10) | G11: =SUM(D11:F11) | H11: =SUMIFS(원장!$H:$H,원장!$A:$A,증감분석!$B11,원장!$D:$D,증감분석!H$9,원장!$E:$E,증감분석!H$10) | I11: =SUMIFS(원장!$H:$H,원장!$A:$A,증감분석!$B11,원장!$D:$D,증감분석!I$9,원장!$E:$E,증감분석!I$10) | J11: =SUMIFS(원장!$H:$H,원장!$A:$A,증감분석!$B11,원장!$D:$D,증감분석!J$9,원장!$E:$E,증감분석!J$10) | K11: =SUMIFS(원장!$H:$H,원장!$A:$A,증감분석!$B11,원장!$D:$D,증감분석!K$9,원장!$E:$E,증감분석!K$10) | L11: =SUM(H11:K11) | M11: =G11+L11 | N11: =SUM($M$11:M11) | P11: =B11 | Q11: =G11 | R11: =-L11 | S11: =N11
B12: 24년 7월 | C12: =IF($B12=참고!$D$5,1,C13+1) | D12: =SUMIFS(원장!$H:$H,원장!$A:$A,증감분석!$B12,원장!$D:$D,증감분석!D$9,원장!$E:$E,증감분석!D$10) | E12: =SUMIFS(원장!$H:$H,원장!$A:$A,증감분석!$B12,원장!$D:$D,증감분석!E$9,원장!$E:$E,증감분석!E$10) | F12: =SUMIFS(원장!$H:$H,원장!$A:$A,증감분석!$B12,원장!$D:$D,증감분석!F$9,원장!$E:$E,증감분석!F$10) | G12: =SUM(D12:F12) | H12: =SUMIFS(원장!$H:$H,원장!$A:$A,증감분석!$B12,원장!$D:$D,증감분석!H$9,원장!$E:$E,증감분석!H$10) | I12: =SUMIFS(원장!$H:$H,원장!$A:$A,증감분석!$B12,원장!$D:$D,증감분석!I$9,원장!$E:$E,증감분석!I$10) | J12: =SUMIFS(원장!$H:$H,원장!$A:$A,증감분석!$B12,원장!$D:$D,증감분석!J$9,원장!$E:$E,증감분석!J$10) | K12: =SUMIFS(원장!$H:$H,원장!$A:$A,증감분석!$B12,원장!$D:$D,증감분석!K$9,원장!$E:$E,증감분석!K$10) | L12: =SUM(H12:K12) | M12: =G12+L12 | N12: =SUM($M$11:M12) | P12: =B12 | Q12: =G12 | R12: =-L12 | S12: =N12
B13: 24년 8월 | C13: =IF($B13=참고!$D$5,1,C14+1) | D13: =SUMIFS(원장!$H:$H,원장!$A:$A,증감분석!$B13,원장!$D:$D,증감분석!D$9,원장!$E:$E,증감분석!D$10) | E13: =SUMIFS(원장!$H:$H,원장!$A:$A,증감분석!$B13,원장!$D:$D,증감분석!E$9,원장!$E:$E,증감분석!E$10) | F13: =SUMIFS(원장!$H:$H,원장!$A:$A,증감분석!$B13,원장!$D:$D,증감분석!F$9,원장!$E:$E,증감분석!F$10) | G13: =SUM(D13:F13) | H13: =SUMIFS(원장!$H:$H,원장!$A:$A,증감분석!$B13,원장!$D:$D,증감분석!H$9,원장!$E:$E,증감분석!H$10) | I13: =SUMIFS(원장!$H:$H,원장!$A:$A,증감분석!$B13,원장!$D:$D,증감분석!I$9,원장!$E:$E,증감분석!I$10) | J13: =SUMIFS(원장!$H:$H,원장!$A:$A,증감분석!$B13,원장!$D:$D,증감분석!J$9,원장!$E:$E,증감분석!J$10) | K13: =SUMIFS(원장!$H:$H,원장!$A:$A,증감분석!$B13,원장!$D:$D,증감분석!K$9,원장!$E:$E,증감분석!K$10) | L13: =SUM(H13:K13) | M13: =G13+L13 | N13: =SUM($M$11:M13) | P13: =B13 | Q13: =G13 | R13: =-L13 | S13: =N13
B14: 24년 9월 | C14: =IF($B14=참고!$D$5,1,C15+1) | D14: =SUMIFS(원장!$H:$H,원장!$A:$A,증감분석!$B14,원장!$D:$D,증감분석!D$9,원장!$E:$E,증감분석!D$10) | E14: =SUMIFS(원장!$H:$H,원장!$A:$A,증감분석!$B14,원장!$D:$D,증감분석!E$9,원장!$E:$E,증감분석!E$10) | F14: =SUMIFS(원장!$H:$H,원장!$A:$A,증감분석!$B14,원장!$D:$D,증감분석!F$9,원장!$E:$E,증감분석!F$10) | G14: =SUM(D14:F14) | H14: =SUMIFS(원장!$H:$H,원장!$A:$A,증감분석!$B14,원장!$D:$D,증감분석!H$9,원장!$E:$E,증감분석!H$10) | I14: =SUMIFS(원장!$H:$H,원장!$A:$A,증감분석!$B14,원장!$D:$D,증감분석!I$9,원장!$E:$E,증감분석!I$10) | J14: =SUMIFS(원장!$H:$H,원장!$A:$A,증감분석!$B14,원장!$D:$D,증감분석!J$9,원장!$E:$E,증감분석!J$10) | K14: =SUMIFS(원장!$H:$H,원장!$A:$A,증감분석!$B14,원장!$D:$D,증감분석!K$9,원장!$E:$E,증감분석!K$10) | L14: =SUM(H14:K14) | M14: =G14+L14 | N14: =SUM($M$11:M14) | P14: =B14 | Q14: =G14 | R14: =-L14 | S14: =N14
B15: 24년 10월 | C15: =IF($B15=참고!$D$5,1,C16+1) | D15: =SUMIFS(원장!$H:$H,원장!$A:$A,증감분석!$B15,원장!$D:$D,증감분석!D$9,원장!$E:$E,증감분석!D$10) | E15: =SUMIFS(원장!$H:$H,원장!$A:$A,증감분석!$B15,원장!$D:$D,증감분석!E$9,원장!$E:$E,증감분석!E$10) | F15: =SUMIFS(원장!$H:$H,원장!$A:$A,증감분석!$B15,원장!$D:$D,증감분석!F$9,원장!$E:$E,증감분석!F$10) | G15: =SUM(D15:F15) | H15: =SUMIFS(원장!$H:$H,원장!$A:$A,증감분석!$B15,원장!$D:$D,증감분석!H$9,원장!$E:$E,증감분석!H$10) | I15: =SUMIFS(원장!$H:$H,원장!$A:$A,증감분석!$B15,원장!$D:$D,증감분석!I$9,원장!$E:$E,증감분석!I$10) | J15: =SUMIFS(원장!$H:$H,원장!$A:$A,증감분석!$B15,원장!$D:$D,증감분석!J$9,원장!$E:$E,증감분석!J$10) | K15: =SUMIFS(원장!$H:$H,원장!$A:$A,증감분석!$B15,원장!$D:$D,증감분석!K$9,원장!$E:$E,증감분석!K$10) | L15: =SUM(H15:K15) | M15: =G15+L15 | N15: =SUM($M$11:M15) | P15: =B15 | Q15: =G15 | R15: =-L15 | S15: =N15
B16: 24년 11월 | C16: =IF($B16=참고!$D$5,1,C17+1) | D16: =SUMIFS(원장!$H:$H,원장!$A:$A,증감분석!$B16,원장!$D:$D,증감분석!D$9,원장!$E:$E,증감분석!D$10) | E16: =SUMIFS(원장!$H:$H,원장!$A:$A,증감분석!$B16,원장!$D:$D,증감분석!E$9,원장!$E:$E,증감분석!E$10) | F16: =SUMIFS(원장!$H:$H,원장!$A:$A,증감분석!$B16,원장!$D:$D,증감분석!F$9,원장!$E:$E,증감분석!F$10) | G16: =SUM(D16:F16) | H16: =SUMIFS(원장!$H:$H,원장!$A:$A,증감분석!$B16,원장!$D:$D,증감분석!H$9,원장!$E:$E,증감분석!H$10) | I16: =SUMIFS(원장!$H:$H,원장!$A:$A,증감분석!$B16,원장!$D:$D,증감분석!I$9,원장!$E:$E,증감분석!I$10) | J16: =SUMIFS(원장!$H:$H,원장!$A:$A,증감분석!$B16,원장!$D:$D,증감분석!J$9,원장!$E:$E,증감분석!J$10) | K16: =SUMIFS(원장!$H:$H,원장!$A:$A,증감분석!$B16,원장!$D:$D,증감분석!K$9,원장!$E:$E,증감분석!K$10) | L16: =SUM(H16:K16) | M16: =G16+L16 | N16: =SUM($M$11:M16) | P16: =B16 | Q16: =G16 | R16: =-L16 | S16: =N16
B17: 24년 12월 | C17: =IF($B17=참고!$D$5,1,C18+1) | D17: =SUMIFS(원장!$H:$H,원장!$A:$A,증감분석!$B17,원장!$D:$D,증감분석!D$9,원장!$E:$E,증감분석!D$10) | E17: =SUMIFS(원장!$H:$H,원장!$A:$A,증감분석!$B17,원장!$D:$D,증감분석!E$9,원장!$E:$E,증감분석!E$10) | F17: =SUMIFS(원장!$H:$H,원장!$A:$A,증감분석!$B17,원장!$D:$D,증감분석!F$9,원장!$E:$E,증감분석!F$10) | G17: =SUM(D17:F17) | H17: =SUMIFS(원장!$H:$H,원장!$A:$A,증감분석!$B17,원장!$D:$D,증감분석!H$9,원장!$E:$E,증감분석!H$10) | I17: =SUMIFS(원장!$H:$H,원장!$A:$A,증감분석!$B17,원장!$D:$D,증감분석!I$9,원장!$E:$E,증감분석!I$10) | J17: =SUMIFS(원장!$H:$H,원장!$A:$A,증감분석!$B17,원장!$D:$D,증감분석!J$9,원장!$E:$E,증감분석!J$10) | K17: =SUMIFS(원장!$H:$H,원장!$A:$A,증감분석!$B17,원장!$D:$D,증감분석!K$9,원장!$E:$E,증감분석!K$10) | L17: =SUM(H17:K17) | M17: =G17+L17 | N17: =SUM($M$11:M17) | P17: =B17 | Q17: =G17 | R17: =-L17 | S17: =N17
B18: 25년 1월 | C18: =IF($B18=참고!$D$5,1,C19+1) | D18: =SUMIFS(원장!$H:$H,원장!$A:$A,증감분석!$B18,원장!$D:$D,증감분석!D$9,원장!$E:$E,증감분석!D$10) | E18: =SUMIFS(원장!$H:$H,원장!$A:$A,증감분석!$B18,원장!$D:$D,증감분석!E$9,원장!$E:$E,증감분석!E$10) | F18: =SUMIFS(원장!$H:$H,원장!$A:$A,증감분석!$B18,원장!$D:$D,증감분석!F$9,원장!$E:$E,증감분석!F$10) | G18: =SUM(D18:F18) | H18: =SUMIFS(원장!$H:$H,원장!$A:$A,증감분석!$B18,원장!$D:$D,증감분석!H$9,원장!$E:$E,증감분석!H$10) | I18: =SUMIFS(원장!$H:$H,원장!$A:$A,증감분석!$B18,원장!$D:$D,증감분석!I$9,원장!$E:$E,증감분석!I$10) | J18: =SUMIFS(원장!$H:$H,원장!$A:$A,증감분석!$B18,원장!$D:$D,증감분석!J$9,원장!$E:$E,증감분석!J$10) | K18: =SUMIFS(원장!$H:$H,원장!$A:$A,증감분석!$B18,원장!$D:$D,증감분석!K$9,원장!$E:$E,증감분석!K$10) | L18: =SUM(H18:K18) | M18: =G18+L18 | N18: =SUM($M$11:M18) | P18: =B18 | Q18: =G18 | R18: =-L18 | S18: =N18
B19: 25년 2월 | C19: =IF($B19=참고!$D$5,1,C20+1) | D19: =SUMIFS(원장!$H:$H,원장!$A:$A,증감분석!$B19,원장!$D:$D,증감분석!D$9,원장!$E:$E,증감분석!D$10) | E19: =SUMIFS(원장!$H:$H,원장!$A:$A,증감분석!$B19,원장!$D:$D,증감분석!E$9,원장!$E:$E,증감분석!E$10) | F19: =SUMIFS(원장!$H:$H,원장!$A:$A,증감분석!$B19,원장!$D:$D,증감분석!F$9,원장!$E:$E,증감분석!F$10) | G19: =SUM(D19:F19) | H19: =SUMIFS(원장!$H:$H,원장!$A:$A,증감분석!$B19,원장!$D:$D,증감분석!H$9,원장!$E:$E,증감분석!H$10) | I19: =SUMIFS(원장!$H:$H,원장!$A:$A,증감분석!$B19,원장!$D:$D,증감분석!I$9,원장!$E:$E,증감분석!I$10) | J19: =SUMIFS(원장!$H:$H,원장!$A:$A,증감분석!$B19,원장!$D:$D,증감분석!J$9,원장!$E:$E,증감분석!J$10) | K19: =SUMIFS(원장!$H:$H,원장!$A:$A,증감분석!$B19,원장!$D:$D,증감분석!K$9,원장!$E:$E,증감분석!K$10) | L19: =SUM(H19:K19) | M19: =G19+L19 | N19: =SUM($M$11:M19) | P19: =B19 | Q19: =G19 | R19: =-L19 | S19: =N19
B20: 25년 3월 | C20: =IF($B20=참고!$D$5,1,C21+1) | D20: =SUMIFS(원장!$H:$H,원장!$A:$A,증감분석!$B20,원장!$D:$D,증감분석!D$9,원장!$E:$E,증감분석!D$10) | E20: =SUMIFS(원장!$H:$H,원장!$A:$A,증감분석!$B20,원장!$D:$D,증감분석!E$9,원장!$E:$E,증감분석!E$10) | F20: =SUMIFS(원장!$H:$H,원장!$A:$A,증감분석!$B20,원장!$D:$D,증감분석!F$9,원장!$E:$E,증감분석!F$10) | G20: =SUM(D20:F20) | H20: =SUMIFS(원장!$H:$H,원장!$A:$A,증감분석!$B20,원장!$D:$D,증감분석!H$9,원장!$E:$E,증감분석!H$10) | I20: =SUMIFS(원장!$H:$H,원장!$A:$A,증감분석!$B20,원장!$D:$D,증감분석!I$9,원장!$E:$E,증감분석!I$10) | J20: =SUMIFS(원장!$H:$H,원장!$A:$A,증감분석!$B20,원장!$D:$D,증감분석!J$9,원장!$E:$E,증감분석!J$10) | K20: =SUMIFS(원장!$H:$H,원장!$A:$A,증감분석!$B20,원장!$D:$D,증감분석!K$9,원장!$E:$E,증감분석!K$10) | L20: =SUM(H20:K20) | M20: =G20+L20 | N20: =SUM($M$11:M20) | P20: =B20 | Q20: =G20 | R20: =-L20 | S20: =N20
B21: 25년 4월 | C21: =IF($B21=참고!$D$5,1,C22+1) | D21: =SUMIFS(원장!$H:$H,원장!$A:$A,증감분석!$B21,원장!$D:$D,증감분석!D$9,원장!$E:$E,증감분석!D$10) | E21: =SUMIFS(원장!$H:$H,원장!$A:$A,증감분석!$B21,원장!$D:$D,증감분석!E$9,원장!$E:$E,증감분석!E$10) | F21: =SUMIFS(원장!$H:$H,원장!$A:$A,증감분석!$B21,원장!$D:$D,증감분석!F$9,원장!$E:$E,증감분석!F$10) | G21: =SUM(D21:F21) | H21: =SUMIFS(원장!$H:$H,원장!$A:$A,증감분석!$B21,원장!$D:$D,증감분석!H$9,원장!$E:$E,증감분석!H$10) | I21: =SUMIFS(원장!$H:$H,원장!$A:$A,증감분석!$B21,원장!$D:$D,증감분석!I$9,원장!$E:$E,증감분석!I$10) | J21: =SUMIFS(원장!$H:$H,원장!$A:$A,증감분석!$B21,원장!$D:$D,증감분석!J$9,원장!$E:$E,증감분석!J$10) | K21: =SUMIFS(원장!$H:$H,원장!$A:$A,증감분석!$B21,원장!$D:$D,증감분석!K$9,원장!$E:$E,증감분석!K$10) | L21: =SUM(H21:K21) | M21: =G21+L21 | N21: =SUM($M$11:M21) | P21: =B21 | Q21: =G21 | R21: =-L21 | S21: =N21
B22: 25년 5월 | C22: =IF($B22=참고!$D$5,1,C23+1) | D22: =SUMIFS(원장!$H:$H,원장!$A:$A,증감분석!$B22,원장!$D:$D,증감분석!D$9,원장!$E:$E,증감분석!D$10) | E22: =SUMIFS(원장!$H:$H,원장!$A:$A,증감분석!$B22,원장!$D:$D,증감분석!E$9,원장!$E:$E,증감분석!E$10) | F22: =SUMIFS(원장!$H:$H,원장!$A:$A,증감분석!$B22,원장!$D:$D,증감분석!F$9,원장!$E:$E,증감분석!F$10) | G22: =SUM(D22:F22) | H22: =SUMIFS(원장!$H:$H,원장!$A:$A,증감분석!$B22,원장!$D:$D,증감분석!H$9,원장!$E:$E,증감분석!H$10) | I22: =SUMIFS(원장!$H:$H,원장!$A:$A,증감분석!$B22,원장!$D:$D,증감분석!I$9,원장!$E:$E,증감분석!I$10) | J22: =SUMIFS(원장!$H:$H,원장!$A:$A,증감분석!$B22,원장!$D:$D,증감분석!J$9,원장!$E:$E,증감분석!J$10) | K22: =SUMIFS(원장!$H:$H,원장!$A:$A,증감분석!$B22,원장!$D:$D,증감분석!K$9,원장!$E:$E,증감분석!K$10) | L22: =SUM(H22:K22) | M22: =G22+L22 | N22: =SUM($M$11:M22) | P22: =B22 | Q22: =G22 | R22: =-L22 | S22: =N22
... B32: 26년 3월 | C32: =IF($B32=참고!$D$5,1,C33+1) | D32: =SUMIFS(원장!$H:$H,원장!$A:$A,증감분석!$B32,원장!$D:$D,증감분석!D$9,원장!$E:$E,증감분석!D$10) | E32: =SUMIFS(원장!$H:$H,원장!$A:$A,증감분석!$B32,원장!$D:$D,증감분석!E$9,원장!$E:$E,증감분석!E$10) | F32: =SUMIFS(원장!$H:$H,원장!$A:$A,증감분석!$B32,원장!$D:$D,증감분석!F$9,원장!$E:$E,증감분석!F$10) | G32: =SUM(D32:F32) | H32: =SUMIFS(원장!$H:$H,원장!$A:$A,증감분석!$B32,원장!$D:$D,증감분석!H$9,원장!$E:$E,증감분석!H$10) | I32: =SUMIFS(원장!$H:$H,원장!$A:$A,증감분석!$B32,원장!$D:$D,증감분석!I$9,원장!$E:$E,증감분석!I$10) | J32: =SUMIFS(원장!$H:$H,원장!$A:$A,증감분석!$B32,원장!$D:$D,증감분석!J$9,원장!$E:$E,증감분석!J$10) | K32: =SUMIFS(원장!$H:$H,원장!$A:$A,증감분석!$B32,원장!$D:$D,증감분석!K$9,원장!$E:$E,증감분석!K$10) | L32: =SUM(H32:K32) | M32: =G32+L32 | N32: =SUM($M$11:M32) | P32: =B32 | Q32: =G32 | R32: =-L32 | S32: =N32

Sheet 증감분석차트

Sheet 참고
A1: =TODAY() | B1: =YEAR(A1) | C1: =MONTH(A1) | D1: =IF(C1-1=0,12,C1-1) | E1: =IF(D1-1=0,12,D1-1) | F1: =IF(E1-1=0,12,E1-1) | G1: =IF(F1-1=0,12,F1-1) | H1: =IF(G1-1=0,12,G1-1) | I1: =IF(H1-1=0,12,H1-1) | J1: =IF(I1-1=0,12,I1-1) | K1: =IF(J1-1=0,12,J1-1) | ... O1: =IF(N1-1=0,12,N1-1)
B2: =RIGHT(B1,2) | C2: =B2-1
B3: =B2&"년" | C3: =C2&"년"
D4: =D1&"월" | E4: =E1&"월" | F4: =F1&"월" | G4: =G1&"월" | H4: =H1&"월" | I4: =I1&"월" | J4: =J1&"월" | K4: =K1&"월" | ... O4: =O1&"월"
D5: =IF(D1>=$C$1,$C$3&" "&D4,$B$3&" "&D4) | E5: =IF(E1>=$C$1,$C$3&" "&E4,$B$3&" "&E4) | F5: =IF(F1>=$C$1,$C$3&" "&F4,$B$3&" "&F4) | G5: =IF(G1>=$C$1,$C$3&" "&G4,$B$3&" "&G4) | H5: =IF(H1>=$C$1,$C$3&" "&H4,$B$3&" "&H4) | I5: =IF(I1>=$C$1,$C$3&" "&I4,$B$3&" "&I4) | J5: =IF(J1>=$C$1,$C$3&" "&J4,$B$3&" "&J4) | K5: =IF(K1>=$C$1,$C$3&" "&K4,$B$3&" "&K4) | ... O5: =IF(O1>=$C$1,$C$3&" "&O4,$B$3&" "&O4)

Sheet 주요정보
E9: 주요 정보 | F9: =회비입출내역!F1 | G9: =회비입출내역!$C$1 | H9: =증감분석!B5 | I9: =증감분석!B6 | J9: =증감분석!$B$7 | K9: 누적
E10: 입금액 | F10: =회비입출내역!$G$4 | G10: =회비입출내역!$D$4 | H10: =증감분석!$G$5 | I10: =증감분석!$G$6 | J10: =증감분석!$G$7 | K10: =회비입출내역!$J$4
E11: 출금액 | F11: =회비입출내역!$G$9 | G11: =회비입출내역!$D$9 | H11: =증감분석!$L$5 | I11: =증감분석!$L$6 | J11: =증감분석!$L$7 | K11: =회비입출내역!$J$9
E12: 입금액 - 출금액 | F12: =SUM(F10:F11) | G12: =SUM(G10:G11) | H12: =SUM(H10:H11) | I12: =SUM(I10:I11) | J12: =SUM(J10:J11) | K12: =SUM(K10:K11)

Sheet 참조
A1: 월별Tab Weekday 함수용
A2: 숫자 | B2: 요일
A3: 1 | B3: 월
A4: 2 | B4: 화
A5: 3 | B5: 수
A6: 4 | B6: 목
A7: 5 | B7: 금
A8: 6 | B8: 토
A9: 7 | B9: 일
